INFO:root:Datetime: 2021-11-18 12:40:03.129387
INFO:root:List Option: ['auto']
INFO:root:Time preprocess image: 0.1769
INFO:root:Time recognize text: 9.2828
INFO:werkzeug:127.0.0.1 - - [18/Nov/2021 12:40:03] "[37mPOST /app HTTP/1.1[0m" 200 -
INFO:root:Datetime: 2021-11-18 13:00:17.209010
INFO:root:List Option: ['inc_contrast']
INFO:root:Time preprocess image: 0.042
INFO:root:Time recognize text: 6.0235
INFO:werkzeug:127.0.0.1 - - [18/Nov/2021 13:00:17] "[37mPOST /app HTTP/1.1[0m" 200 -
WARNING:flask_cors.core:Unknown option passed to Flask-CORS: origin
INFO:root:Datetime: 2021-11-18 13:01:49.822566
INFO:root:List Option: ['dec_contrast']
INFO:root:Time preprocess image: 0.045
INFO:root:Time recognize text: 7.816
INFO:werkzeug:127.0.0.1 - - [18/Nov/2021 13:01:49] "[37mPOST /app HTTP/1.1[0m" 200 -
WARNING:flask_cors.core:Unknown option passed to Flask-CORS: origin
INFO:root:Datetime: 2021-11-18 13:02:21.924779
INFO:root:List Option: ['blur_gaussian']
INFO:root:Time preprocess image: 0.007
INFO:root:Time recognize text: 6.3913
INFO:werkzeug:127.0.0.1 - - [18/Nov/2021 13:02:21] "[37mPOST /app HTTP/1.1[0m" 200 -
WARNING:flask_cors.core:Unknown option passed to Flask-CORS: origin
INFO:root:Datetime: 2021-11-18 13:02:35.720580
INFO:root:List Option: ['blur_bilateral']
INFO:root:Time preprocess image: 0.0231
INFO:root:Time recognize text: 6.3272
INFO:werkzeug:127.0.0.1 - - [18/Nov/2021 13:02:35] "[37mPOST /app HTTP/1.1[0m" 200 -
WARNING:flask_cors.core:Unknown option passed to Flask-CORS: origin
ERROR:main:Exception on /app [POST]
Traceback (most recent call last):
  File "C:\Users\ngoct\anaconda3\lib\site-packages\flask\app.py", line 2447, in wsgi_app
    response = self.full_dispatch_request()
  File "C:\Users\ngoct\anaconda3\lib\site-packages\flask\app.py", line 1952, in full_dispatch_request
    rv = self.handle_user_exception(e)
  File "C:\Users\ngoct\anaconda3\lib\site-packages\flask_cors\extension.py", line 165, in wrapped_function
    return cors_after_request(app.make_response(f(*args, **kwargs)))
  File "C:\Users\ngoct\anaconda3\lib\site-packages\flask\app.py", line 1821, in handle_user_exception
    reraise(exc_type, exc_value, tb)
  File "C:\Users\ngoct\anaconda3\lib\site-packages\flask\_compat.py", line 39, in reraise
    raise value
  File "C:\Users\ngoct\anaconda3\lib\site-packages\flask\app.py", line 1950, in full_dispatch_request
    rv = self.dispatch_request()
  File "C:\Users\ngoct\anaconda3\lib\site-packages\flask\app.py", line 1936, in dispatch_request
    return self.view_functions[rule.endpoint](**req.view_args)
  File "C:\Users\ngoct\anaconda3\lib\site-packages\flask_cors\decorator.py", line 128, in wrapped_function
    resp = make_response(f(*args, **kwargs))
  File "main.py", line 31, in process_image
    image, text = image_process(detector = detector, reader = reader, image=image, lst_encode=lst)
  File "D:\CS406\IDCard_OCR\server\handle.py", line 50, in image_process
    image_result = preprocess(image, lst_decode)
  File "D:\CS406\IDCard_OCR\server\handle.py", line 29, in preprocess
    image = getattr(libs, "auto_detect")(image)
  File "D:\CS406\IDCard_OCR\server\src\libs\detect_object.py", line 14, in auto_detect
    corners = auto_corners(image)
  File "D:\CS406\IDCard_OCR\server\src\libs\corners_detector.py", line 8, in auto_corners
    image = enhancement.inc_contract(image, contrast=contrast, brightness=brightness)
AttributeError: module 'src.libs.enhancement' has no attribute 'inc_contract'
INFO:werkzeug:127.0.0.1 - - [18/Nov/2021 13:02:41] "[35m[1mPOST /app HTTP/1.1[0m" 500 -
INFO:root:Datetime: 2021-11-18 13:11:54.737758
ERROR:main:Exception on /app [POST]
Traceback (most recent call last):
  File "C:\Users\ngoct\anaconda3\lib\site-packages\flask\app.py", line 2447, in wsgi_app
    response = self.full_dispatch_request()
  File "C:\Users\ngoct\anaconda3\lib\site-packages\flask\app.py", line 1952, in full_dispatch_request
    rv = self.handle_user_exception(e)
  File "C:\Users\ngoct\anaconda3\lib\site-packages\flask_cors\extension.py", line 165, in wrapped_function
    return cors_after_request(app.make_response(f(*args, **kwargs)))
  File "C:\Users\ngoct\anaconda3\lib\site-packages\flask\app.py", line 1821, in handle_user_exception
    reraise(exc_type, exc_value, tb)
  File "C:\Users\ngoct\anaconda3\lib\site-packages\flask\_compat.py", line 39, in reraise
    raise value
  File "C:\Users\ngoct\anaconda3\lib\site-packages\flask\app.py", line 1950, in full_dispatch_request
    rv = self.dispatch_request()
  File "C:\Users\ngoct\anaconda3\lib\site-packages\flask\app.py", line 1936, in dispatch_request
    return self.view_functions[rule.endpoint](**req.view_args)
  File "C:\Users\ngoct\anaconda3\lib\site-packages\flask_cors\decorator.py", line 128, in wrapped_function
    resp = make_response(f(*args, **kwargs))
  File "main.py", line 31, in process_image
    image, text = image_process(detector = detector, reader = reader, image=image, lst_encode=lst)
  File "D:\CS406\IDCard_OCR\server\handle.py", line 63, in image_process
    logging.info(f'List Option: {lst_decode}')
NameError: name 'lst_decode' is not defined
INFO:werkzeug:127.0.0.1 - - [18/Nov/2021 13:11:54] "[35m[1mPOST /app HTTP/1.1[0m" 500 -
INFO:root:Datetime: 2021-11-18 13:13:30.888042
ERROR:main:Exception on /app [POST]
Traceback (most recent call last):
  File "C:\Users\ngoct\anaconda3\lib\site-packages\flask\app.py", line 2447, in wsgi_app
    response = self.full_dispatch_request()
  File "C:\Users\ngoct\anaconda3\lib\site-packages\flask\app.py", line 1952, in full_dispatch_request
    rv = self.handle_user_exception(e)
  File "C:\Users\ngoct\anaconda3\lib\site-packages\flask_cors\extension.py", line 165, in wrapped_function
    return cors_after_request(app.make_response(f(*args, **kwargs)))
  File "C:\Users\ngoct\anaconda3\lib\site-packages\flask\app.py", line 1821, in handle_user_exception
    reraise(exc_type, exc_value, tb)
  File "C:\Users\ngoct\anaconda3\lib\site-packages\flask\_compat.py", line 39, in reraise
    raise value
  File "C:\Users\ngoct\anaconda3\lib\site-packages\flask\app.py", line 1950, in full_dispatch_request
    rv = self.dispatch_request()
  File "C:\Users\ngoct\anaconda3\lib\site-packages\flask\app.py", line 1936, in dispatch_request
    return self.view_functions[rule.endpoint](**req.view_args)
  File "C:\Users\ngoct\anaconda3\lib\site-packages\flask_cors\decorator.py", line 128, in wrapped_function
    resp = make_response(f(*args, **kwargs))
  File "main.py", line 31, in process_image
    image, text = image_process(detector = detector, reader = reader, image=image, lst_encode=lst)
  File "D:\CS406\IDCard_OCR\server\handle.py", line 63, in image_process
    logging.info(f'List Option: {lst_decode}')
NameError: name 'lst_decode' is not defined
INFO:werkzeug:127.0.0.1 - - [18/Nov/2021 13:13:30] "[35m[1mPOST /app HTTP/1.1[0m" 500 -
INFO:root:Datetime: 2021-11-18 13:14:47.560239
INFO:root:List Option: ['inc_contrast']
INFO:root:Time preprocess image: 0.05
INFO:root:Time recognize text: 7.52
INFO:werkzeug:127.0.0.1 - - [18/Nov/2021 13:14:47] "[37mPOST /app HTTP/1.1[0m" 200 -
WARNING:flask_cors.core:Unknown option passed to Flask-CORS: origin
ERROR:main:Exception on /app [POST]
Traceback (most recent call last):
  File "C:\Users\ngoct\anaconda3\lib\site-packages\flask\app.py", line 2447, in wsgi_app
    response = self.full_dispatch_request()
  File "C:\Users\ngoct\anaconda3\lib\site-packages\flask\app.py", line 1952, in full_dispatch_request
    rv = self.handle_user_exception(e)
  File "C:\Users\ngoct\anaconda3\lib\site-packages\flask_cors\extension.py", line 165, in wrapped_function
    return cors_after_request(app.make_response(f(*args, **kwargs)))
  File "C:\Users\ngoct\anaconda3\lib\site-packages\flask\app.py", line 1821, in handle_user_exception
    reraise(exc_type, exc_value, tb)
  File "C:\Users\ngoct\anaconda3\lib\site-packages\flask\_compat.py", line 39, in reraise
    raise value
  File "C:\Users\ngoct\anaconda3\lib\site-packages\flask\app.py", line 1950, in full_dispatch_request
    rv = self.dispatch_request()
  File "C:\Users\ngoct\anaconda3\lib\site-packages\flask\app.py", line 1936, in dispatch_request
    return self.view_functions[rule.endpoint](**req.view_args)
  File "C:\Users\ngoct\anaconda3\lib\site-packages\flask_cors\decorator.py", line 128, in wrapped_function
    resp = make_response(f(*args, **kwargs))
  File "main.py", line 31, in process_image
    image, text = image_process(detector = detector, reader = reader, image=image, lst_encode=lst)
  File "D:\CS406\IDCard_OCR\server\handle.py", line 50, in image_process
    image_result = preprocess(image, lst_decode)
  File "D:\CS406\IDCard_OCR\server\handle.py", line 29, in preprocess
    image = getattr(libs, "auto_detect")(image)
  File "D:\CS406\IDCard_OCR\server\src\libs\detect_object.py", line 14, in auto_detect
    corners = auto_corners(image)
  File "D:\CS406\IDCard_OCR\server\src\libs\corners_detector.py", line 8, in auto_corners
    image = enhancement.inc_contrast(image, contract=contract, brightness=brightness)
TypeError: inc_contrast() got an unexpected keyword argument 'contract'
INFO:werkzeug:127.0.0.1 - - [18/Nov/2021 13:14:52] "[35m[1mPOST /app HTTP/1.1[0m" 500 -
WARNING:flask_cors.core:Unknown option passed to Flask-CORS: origin
ERROR:main:Exception on /app [POST]
Traceback (most recent call last):
  File "C:\Users\ngoct\anaconda3\lib\site-packages\flask\app.py", line 2447, in wsgi_app
    response = self.full_dispatch_request()
  File "C:\Users\ngoct\anaconda3\lib\site-packages\flask\app.py", line 1952, in full_dispatch_request
    rv = self.handle_user_exception(e)
  File "C:\Users\ngoct\anaconda3\lib\site-packages\flask_cors\extension.py", line 165, in wrapped_function
    return cors_after_request(app.make_response(f(*args, **kwargs)))
  File "C:\Users\ngoct\anaconda3\lib\site-packages\flask\app.py", line 1821, in handle_user_exception
    reraise(exc_type, exc_value, tb)
  File "C:\Users\ngoct\anaconda3\lib\site-packages\flask\_compat.py", line 39, in reraise
    raise value
  File "C:\Users\ngoct\anaconda3\lib\site-packages\flask\app.py", line 1950, in full_dispatch_request
    rv = self.dispatch_request()
  File "C:\Users\ngoct\anaconda3\lib\site-packages\flask\app.py", line 1936, in dispatch_request
    return self.view_functions[rule.endpoint](**req.view_args)
  File "C:\Users\ngoct\anaconda3\lib\site-packages\flask_cors\decorator.py", line 128, in wrapped_function
    resp = make_response(f(*args, **kwargs))
  File "main.py", line 31, in process_image
    image, text = image_process(detector = detector, reader = reader, image=image, lst_encode=lst)
  File "D:\CS406\IDCard_OCR\server\handle.py", line 50, in image_process
    image_result = preprocess(image, lst_decode)
  File "D:\CS406\IDCard_OCR\server\handle.py", line 29, in preprocess
    image = getattr(libs, "auto_detect")(image)
  File "D:\CS406\IDCard_OCR\server\src\libs\detect_object.py", line 14, in auto_detect
    corners = auto_corners(image)
  File "D:\CS406\IDCard_OCR\server\src\libs\corners_detector.py", line 8, in auto_corners
    image = enhancement.inc_contrast(image, contract=contract, brightness=brightness)
TypeError: inc_contrast() got an unexpected keyword argument 'contract'
INFO:werkzeug:127.0.0.1 - - [18/Nov/2021 13:15:08] "[35m[1mPOST /app HTTP/1.1[0m" 500 -
WARNING:flask_cors.core:Unknown option passed to Flask-CORS: origin
ERROR:main:Exception on /app [POST]
Traceback (most recent call last):
  File "C:\Users\ngoct\anaconda3\lib\site-packages\flask\app.py", line 2447, in wsgi_app
    response = self.full_dispatch_request()
  File "C:\Users\ngoct\anaconda3\lib\site-packages\flask\app.py", line 1952, in full_dispatch_request
    rv = self.handle_user_exception(e)
  File "C:\Users\ngoct\anaconda3\lib\site-packages\flask_cors\extension.py", line 165, in wrapped_function
    return cors_after_request(app.make_response(f(*args, **kwargs)))
  File "C:\Users\ngoct\anaconda3\lib\site-packages\flask\app.py", line 1821, in handle_user_exception
    reraise(exc_type, exc_value, tb)
  File "C:\Users\ngoct\anaconda3\lib\site-packages\flask\_compat.py", line 39, in reraise
    raise value
  File "C:\Users\ngoct\anaconda3\lib\site-packages\flask\app.py", line 1950, in full_dispatch_request
    rv = self.dispatch_request()
  File "C:\Users\ngoct\anaconda3\lib\site-packages\flask\app.py", line 1936, in dispatch_request
    return self.view_functions[rule.endpoint](**req.view_args)
  File "C:\Users\ngoct\anaconda3\lib\site-packages\flask_cors\decorator.py", line 128, in wrapped_function
    resp = make_response(f(*args, **kwargs))
  File "main.py", line 31, in process_image
    image, text = image_process(detector = detector, reader = reader, image=image, lst_encode=lst)
  File "D:\CS406\IDCard_OCR\server\handle.py", line 50, in image_process
    image_result = preprocess(image, lst_decode)
  File "D:\CS406\IDCard_OCR\server\handle.py", line 29, in preprocess
    image = getattr(libs, "auto_detect")(image)
  File "D:\CS406\IDCard_OCR\server\src\libs\detect_object.py", line 14, in auto_detect
    corners = auto_corners(image)
  File "D:\CS406\IDCard_OCR\server\src\libs\corners_detector.py", line 8, in auto_corners
    image = enhancement.inc_contrast(image, contract=contract, brightness=brightness)
TypeError: inc_contrast() got an unexpected keyword argument 'contract'
INFO:werkzeug:127.0.0.1 - - [18/Nov/2021 13:15:22] "[35m[1mPOST /app HTTP/1.1[0m" 500 -
INFO:root:Datetime: 2021-11-18 13:17:55.905316
INFO:root:List Option: ['auto']
INFO:root:Time preprocess image: 0.094
INFO:root:Time recognize text: 8.387
INFO:werkzeug:127.0.0.1 - - [18/Nov/2021 13:17:55] "[37mPOST /app HTTP/1.1[0m" 200 -
